Workbook

Sheet DADOS MATRIZ
H2: INDIVUDUAL (MM) | N2: Armazenamento (TUBOS) (M) | Q2: EMBALAGEM (M) | X2: Reembalagem (Master) (M)
B3: Produto | C3: Descrição | D3: Linha | E3: Família | F3: Unidade | G3: Tipo Embalagem | H3: Peso Bruto (produto + embalagem) | I3: Comprimento | J3: Altura | K3: Largura | L3: Cubagem | M3: Código de Barras | N3: Altur.Armaze | O3: Compr.Armaze | P3: Largu.Armaze | Q3: Larg.Emb | R3: Alt.Emb | S3: Compr.Emb | T3: Quantidade Embalagem | U3: Pos.IPI/NCM | V3: Aliq. IPI | W3: Código de Barras | X3: Larg.Reemb | Y3: Alt.Reemb | Z3: Compr.Reemb | AA3: Cubagem | AB3: Quantidade | AC3: Código de Barras | AD3: Data de validade
B4: 23 | C4: TUBO PVC SOLDAVEL - 6M - 20MM | D4: TUBOS PVC SOLDAVEL | E4: AF | F4: BR | G4: Amarrados | H4: 0.82 | I4: 6000 | J4: 20 | K4: 20 | L4: =J4*I4*K4 -> 2400000 | M4: 7897801304009 | N4: 0.023 | O4: 6 | P4: 0.023 | Q4: 0.085 | R4: 0.085 | S4: 6 | T4: 12 | U4: 3917.23.00 | V4: 0 | W4: 17897801304006 | X4: NÃO APLICA | Y4: NÃO APLICA | Z4: NÃO APLICA | AB4: 0 | AC4: 27897801304003 | AD4: Validade indeterminada
B5: 24 | C5: TUBO PVC SOLDAVEL - 6M - 25MM | D5: TUBOS PVC SOLDAVEL | E5: AF | F5: BR | G5: Amarrados | H5: 1.172 | I5: 6000 | J5: 25 | K5: 25 | L5: =J5*I5*K5 -> 3750000 | M5: 7897801304016 | N5: 0.027 | O5: 6 | P5: 0.027 | Q5: 0.085 | R5: 0.085 | S5: 6 | T5: 8 | U5: 3917.23.00 | V5: 0 | W5: 17897801304013 | X5: NÃO APLICA | Y5: NÃO APLICA | Z5: NÃO APLICA | AB5: 0 | AC5: 27897801304010 | AD5: Validade indeterminada
B6: 25 | C6: TUBO PVC SOLDAVEL - 6M - 32MM | D6: TUBOS PVC SOLDAVEL | E6: AF | F6: BR | G6: Amarrados | H6: 1.845 | I6: 6000 | J6: 32 | K6: 32 | L6: =J6*I6*K6 -> 6144000 | M6: 7897801304023 | N6: 0.035 | O6: 6 | P6: 0.035 | Q6: 0.13 | R6: 0.09 | S6: 6 | T6: 10 | U6: 3917.23.00 | V6: 0 | W6: 17897801304020 | X6: NÃO APLICA | Y6: NÃO APLICA | Z6: NÃO APLICA | AB6: 0 | AC6: 27897801304027 | AD6: Validade indeterminada
B7: 26 | C7: TUBO PVC SOLDAVEL - 6M - 40MM | D7: TUBOS PVC SOLDAVEL | E7: AF | F7: BR | G7: Amarrados | H7: 2.645 | I7: 6000 | J7: 40 | K7: 40 | L7: =J7*I7*K7 -> 9600000 | M7: 7897801304030 | N7: 0.045 | O7: 6 | P7: 0.045 | Q7: 0.12 | R7: 0.075 | S7: 6 | T7: 5 | U7: 3917.23.00 | V7: 0 | W7: 17897801304037 | X7: NÃO APLICA | Y7: NÃO APLICA | Z7: NÃO APLICA | AB7: 0 | AC7: 27897801304034 | AD7: Validade indeterminada
B8: 27 | C8: TUBO PVC SOLDAVEL - 6M - 50MM | D8: TUBOS PVC SOLDAVEL | E8: AF | F8: BR | G8: Amarrados | H8: 4.122 | I8: 6000 | J8: 50 | K8: 50 | L8: =J8*I8*K8 -> 15000000 | M8: 7897801304047 | N8: 0.055 | O8: 6 | P8: 0.055 | Q8: 0.17 | R8: 0.11 | S8: 6 | T8: 5 | U8: 3917.23.00 | V8: 0 | W8: 17897801304044 | X8: NÃO APLICA | Y8: NÃO APLICA | Z8: NÃO APLICA | AB8: 0 | AC8: 27897801304041 | AD8: Validade indeterminada
B9: 28 | C9: TUBO PVC SOLDAVEL - 6M - 60MM | D9: TUBOS PVC SOLDAVEL | E9: AF | F9: BR | G9: Amarrados | H9: 5.382 | I9: 6000 | J9: 60 | K9: 60 | L9: =J9*I9*K9 -> 21600000 | M9: 7897801304054 | N9: 0.067 | O9: 6 | P9: 0.067 | Q9: 0.125 | R9: 0.12 | S9: 6 | T9: 3 | U9: 3917.23.00 | V9: 0 | W9: 17897801304051 | X9: NÃO APLICA | Y9: NÃO APLICA | Z9: NÃO APLICA | AB9: 0 | AC9: 27897801304058 | AD9: Validade indeterminada
B10: 29 | C10: TUBO PVC SOLDAVEL - 6M - 75MM | D10: TUBOS PVC SOLDAVEL | E10: AF | F10: BR | G10: Amarrados | H10: 8.53 | I10: 6000 | J10: 75 | K10: 75 | L10: =J10*I10*K10 -> 33750000 | M10: 7897801308564 | N10: 0.083 | O10: 6 | P10: 0.083 | Q10: 0.0752 | R10: 0.0752 | S10: 6 | T10: 1 | U10: 3917.23.00 | V10: 0 | W10: 17897801308561 | X10: NÃO APLICA | Y10: NÃO APLICA | Z10: NÃO APLICA | AB10: 0 | AC10: 27897801308568 | AD10: Validade indeterminada
B11: 30 | C11: TUBO PVC SOLDAVEL - 6M - 85MM | D11: TUBOS PVC SOLDAVEL | E11: AF | F11: BR | G11: Amarrados | H11: 10.85 | I11: 6000 | J11: 85 | K11: 85 | L11: =J11*I11*K11 -> 43350000 | M11: 7897801308588 | N11: 0.095 | O11: 6 | P11: 0.095 | Q11: 0.0852 | R11: 0.0852 | S11: 6 | T11: 1 | U11: 3917.23.00 | V11: 0 | W11: 17897801308585 | X11: NÃO APLICA | Y11: NÃO APLICA | Z11: NÃO APLICA | AB11: 0 | AC11: 27897801308582 | AD11: Validade indeterminada
B12: 31 | C12: TUBO PVC SOLDAVEL - 6M - 110MM | D12: TUBOS PVC SOLDAVEL | E12: AF | F12: BR | G12: Amarrados | H12: 18.25 | I12: 6000 | J12: 110 | K12: 110 | L12: =J12*I12*K12 -> 72600000 | M12: 7897801308595 | N12: 0.122 | O12: 6 | P12: 0.122 | Q12: 0.1102 | R12: 0.1102 | S12: 6 | T12: 1 | U12: 3917.23.00 | V12: 0 | W12: 17897801308592 | X12: NÃO APLICA | Y12: NÃO APLICA | Z12: NÃO APLICA | AB12: 0 | AC12: 27897801308599 | AD12: Validade indeterminada
B13: 32 | C13: TUBO PVC SOLDAVEL - 3M - 20MM | D13: TUBOS PVC SOLDAVEL | E13: AF | F13: BR | G13: Amarrados | H13: 0.42 | I13: 3000 | J13: 20 | K13: 20 | L13: =J13*I13*K13 -> 1200000 | M13: 7897801304306 | N13: 0.0202 | O13: 3 | P13: 0.0202 | Q13: 0.085 | R13: 0.085 | S13: 3 | T13: 12 | U13: 3917.23.00 | V13: 0 | W13: 17897801304303 | X13: NÃO APLICA | Y13: NÃO APLICA | Z13: NÃO APLICA | AB13: 0 | AC13: 27897801304300 | AD13: Validade indeterminada
B14: 33 | C14: TUBO PVC SOLDAVEL - 3M - 25MM | D14: TUBOS PVC SOLDAVEL | E14: AF | F14: BR | G14: Amarrados | H14: 0.579 | I14: 3000 | J14: 25 | K14: 25 | L14: =J14*I14*K14 -> 1875000 | M14: 7897801304313 | N14: 0.0252 | O14: 3 | P14: 0.0252 | Q14: 0.1 | R14: 0.09 | S14: 3 | T14: 8 | U14: 3917.23.00 | V14: 0 | W14: 17897801304310 | X14: NÃO APLICA | Y14: NÃO APLICA | Z14: NÃO APLICA | AB14: 0 | AC14: 27897801304317 | AD14: Validade indeterminada
B15: 34 | C15: TUBO PVC SOLDAVEL - 3M - 32MM | D15: TUBOS PVC SOLDAVEL | E15: AF | F15: BR | G15: Amarrados | H15: 0.925 | I15: 3000 | J15: 32 | K15: 32 | L15: =J15*I15*K15 -> 3072000 | M15: 7897801308991 | N15: 0.0322 | O15: 3 | P15: 0.0322 | Q15: 0.13 | R15: 0.09 | S15: 3 | T15: 10 | U15: 3917.23.00 | V15: 0 | W15: 17897801308998 | X15: NÃO APLICA | Y15: NÃO APLICA | Z15: NÃO APLICA | AB15: 0 | AC15: 27897801308995 | AD15: Validade indeterminada
... B22: 52 | C22: TUBO ULTRATERM 3M - 28MM | D22: CPVC - ULTRATERM - TUBOS | E22: AQ | F22: BR | G22: Amarrados | H22: 0.95 | I22: 3000 | J22: 28 | K22: 28 | L22: =J22*I22*K22 -> 2352000 | M22: 7897801320283 | N22: 0.028 | O22: 3 | P22: 0.028 | Q22: 0.028 | R22: 3 | S22: 0.028 | T22: 10 | U22: 3917.23.00 | V22: 0 | W22: 17897801320280 | X22: NÃO APLICA | Y22: NÃO APLICA | Z22: NÃO APLICA | AB22: 0 | AC22: 27897801320287 | AD22: Validade indeterminada
B23: 78 | C23: RALO QUADRADO OCULTO 10x10 cm KRONA | D23: CAIXAS E RALOS | E23: ESGOTO | F23: PC | G23: Blister | H23: 0.715 | I23: 125 | J23: 48 | K23: 125 | L23: =J23*I23*K23 -> 750000 | M23: 7898708518384 | N23: NÃO APLICA | O23: NÃO APLICA | P23: NÃO APLICA | Q23: 0.1 | R23: 0.024 | S23: 0.1 | T23: 1 | U23: 3917.40.90 | V23: 0 | W23: 17898708518381 | X23: 0.066 | Y23: 0.25 | Z23: 0.165 | AA23: =Y23*X23*Z23 -> 0.0027225 | AB23: 20 | AC23: 27898708518388 | AD23: Validade indeterminada
B24: 79 | C24: RALO QUADRADO OCULTO 15x15 cm KRONA | D24: CAIXAS E RALOS | E24: ESGOTO | F24: PC | G24: Blister | H24: 1.083 | I24: 195 | J24: 39 | K24: 195 | L24: =J24*I24*K24 -> 1482975 | M24: 7898708518391 | N24: NÃO APLICA | O24: NÃO APLICA | P24: NÃO APLICA | Q24: 0.152 | R24: 0.02 | S24: 0.152 | T24: 1 | U24: 3917.40.90 | V24: 0 | W24: 17898708518398 | X24: 0.045 | Y24: 0.222 | Z24: 0.223 | AA24: =Y24*X24*Z24 -> 0.00222777 | AB24: 45 | AC24: 27898708518395 | AD24: Validade indeterminada
B25: 80 | C25: RALO LINEAR PVC SECO 50CM OCULTO KRONA | D25: CAIXAS E RALOS | E25: ESGOTO | F25: PC | G25: Filme | H25: 0.696 | I25: 523 | J25: 25 | K25: 100 | L25: =J25*I25*K25 -> 1307500 | M25: 7898708518407 | N25: NÃO APLICA | O25: NÃO APLICA | P25: NÃO APLICA | Q25: 0.076 | R25: 0.012 | S25: 0.248 | T25: 1 | U25: 3917.40.90 | V25: 0 | W25: 17898708518404 | X25: 0.105 | Y25: 0.075 | Z25: 0.53 | AA25: =Y25*X25*Z25 -> 0.00417375 | AB25: 30 | AC25: 27898708518401 | AD25: Validade indeterminada
B26: 81 | C26: RALO LINEAR PVC SECO 50CM ACAB. POLIDO KRONA | D26: CAIXAS E RALOS | E26: ESGOTO | F26: PC | G26: Caixa | H26: 0.514 | I26: 523 | J26: 25 | K26: 100 | L26: =J26*I26*K26 -> 1307500 | M26: 7898708518414 | N26: NÃO APLICA | O26: NÃO APLICA | P26: NÃO APLICA | Q26: 0.076 | R26: 0.026 | S26: 0.248 | T26: 1 | U26: 3917.40.90 | V26: 0 | W26: 17898708518411 | X26: 0.105 | Y26: 0.075 | Z26: 0.53 | AA26: =Y26*X26*Z26 -> 0.00417375 | AB26: 24 | AC26: 27898708518418 | AD26: Validade indeterminada
B27: 82 | C27: RALO LINEAR PVC SIFONADO 50CM OCULTO KRONA | D27: CAIXAS E RALOS | E27: ESGOTO | F27: PC | G27: Filme | H27: 1.064 | I27: 523 | J27: 25 | K27: 100 | L27: =J27*I27*K27 -> 1307500 | M27: 7898708518421 | N27: NÃO APLICA | O27: NÃO APLICA | P27: NÃO APLICA | Q27: 0.076 | R27: 0.012 | S27: 0.248 | T27: 1 | U27: 3917.40.90 | V27: 0 | W27: 17898708518428 | X27: 0.105 | Y27: 0.075 | Z27: 0.53 | AA27: =Y27*X27*Z27 -> 0.00417375 | AB27: 30 | AC27: 27898708518425 | AD27: Validade indeterminada
B28: 83 | C28: RALO LINEAR PVC SIFONADO 50CM ACAB. POLIDO KRONA | D28: CAIXAS E RALOS | E28: ESGOTO | F28: PC | G28: Caixa | H28: 0.729 | I28: 523 | J28: 25 | K28: 100 | L28: =J28*I28*K28 -> 1307500 | M28: 7898708518438 | N28: NÃO APLICA | O28: NÃO APLICA | P28: NÃO APLICA | Q28: 0.076 | R28: 0.026 | S28: 0.248 | T28: 1 | U28: 3917.40.90 | V28: 0 | W28: 17898708518435 | X28: 0.105 | Y28: 0.075 | Z28: 0.53 | AA28: =Y28*X28*Z28 -> 0.00417375 | AB28: 24 | AC28: 27898708518432 | AD28: Validade indeterminada
B29: 84 | C29: RALO LINEAR PVC SECO 75CM SAIDA CENTRAL OCULTO KRONA | D29: CAIXAS E RALOS | E29: ESGOTO | F29: PC | G29: Filme | H29: 0.495 | I29: 773 | J29: 33 | K29: 100 | L29: =J29*I29*K29 -> 2550900 | M29: 7898708518445 | N29: NÃO APLICA | O29: NÃO APLICA | P29: NÃO APLICA | Q29: 0.076 | R29: 0.012 | S29: 0.248 | T29: 1 | U29: 3917.40.90 | V29: 0 | W29: 17898708518442 | X29: 0.105 | Y29: 0.075 | Z29: 0.775 | AA29: =Y29*X29*Z29 -> 0.006103125 | AB29: 20 | AC29: 27898708518449 | AD29: Validade indeterminada
B30: 85 | C30: RALO LINEAR PVC SECO 75CM SAIDA CENTRAL POLIDO KRONA | D30: CAIXAS E RALOS | E30: ESGOTO | F30: PC | G30: Caixa | H30: 0.197 | I30: 773 | J30: 33 | K30: 100 | L30: =J30*I30*K30 -> 2550900 | M30: 7898708518452 | N30: NÃO APLICA | O30: NÃO APLICA | P30: NÃO APLICA | Q30: 0.076 | R30: 0.026 | S30: 0.748 | T30: 1 | U30: 3917.40.90 | V30: 0 | W30: 17898708518459 | X30: 0.105 | Y30: 0.075 | Z30: 0.775 | AA30: =Y30*X30*Z30 -> 0.006103125 | AB30: 18 | AC30: 27898708518456 | AD30: Validade indeterminada
B31: 86 | C31: RALO LINEAR PVC SIFONADO 75CM SAIDA CENTRAL OCULTO KRONA | D31: CAIXAS E RALOS | E31: ESGOTO | F31: PC | G31: Filme | H31: 0.71 | I31: 773 | J31: 33 | K31: 100 | L31: =J31*I31*K31 -> 2550900 | M31: 7898708518469 | N31: NÃO APLICA | O31: NÃO APLICA | P31: NÃO APLICA | Q31: 0.076 | R31: 0.012 | S31: 0.248 | T31: 1 | U31: 3917.40.90 | V31: 0 | W31: 17898708518466 | X31: 0.105 | Y31: 0.075 | Z31: 0.775 | AA31: =Y31*X31*Z31 -> 0.006103125 | AB31: 20 | AC31: 27898708518463 | AD31: Validade indeterminada
B32: 87 | C32: RALO LINEAR PVC SIFONADO 75CM SAIDA CENTRAL POLIDO KRONA | D32: CAIXAS E RALOS | E32: ESGOTO | F32: PC | G32: Caixa | H32: 0.424 | I32: 773 | J32: 33 | K32: 100 | L32: =J32*I32*K32 -> 2550900 | M32: 7898708518476 | N32: NÃO APLICA | O32: NÃO APLICA | P32: NÃO APLICA | Q32: 0.076 | R32: 0.026 | S32: 0.748 | T32: 1 | U32: 3917.40.90 | V32: 0 | W32: 17898708518473 | X32: 0.105 | Y32: 0.075 | Z32: 0.775 | AA32: =Y32*X32*Z32 -> 0.006103125 | AB32: 18 | AC32: 27898708518470 | AD32: Validade indeterminada
B33: 88 | C33: SIFAO 50MM PARA RALOS KRONA | D33: CAIXAS E RALOS | E33: ESGOTO | F33: PC | G33: Blister | H33: 0.059 | I33: 50 | J33: 80 | K33: 50 | L33: =J33*I33*K33 -> 200000 | M33: 7898708518483 | N33: NÃO APLICA | O33: NÃO APLICA | P33: NÃO APLICA | Q33: 0.054 | R33: 0.185 | S33: 0.131 | T33: 1 | U33: 3917.40.90 | V33: 0 | W33: 17898708518480 | X33: 0.27 | Y33: 0.27 | Z33: 0.33 | AA33: =Y33*X33*Z33 -> 0.024057 | AB33: 20 | AC33: 27898708518487 | AD33: Validade indeterminada
B34: 89 | C34: BOLSA ACOPLAVEL CX SIFONADA 100MM PVC | D34: CAIXAS E RALOS | E34: ESGOTO | F34: PC | G34: Sacos | H34: 0.056 | I34: 95 | J34: 30 | K34: 95 | L34: =J34*I34*K34 -> 270750 | M34: 7898708518490 | N34: NÃO APLICA | O34: NÃO APLICA | P34: NÃO APLICA | Q34: 0.19 | R34: 0.03 | S34: 0.265 | T34: 1 | U34: 3917.40.90 | V34: 0 | W34: 17898708518497 | X34: 0.27 | Y34: 0.27 | Z34: 0.33 | AA34: =Y34*X34*Z34 -> 0.024057 | AB34: 20 | AC34: 27898708518494 | AD34: Validade indeterminada
B35: 90 | C35: BOLSA ACOPLAVEL CX SIFONADA 150MM PVC | D35: CAIXAS E RALOS | E35: ESGOTO | F35: PC | G35: Sacos | H35: 0.092 | I35: 143 | J35: 30 | K35: 143 | L35: =J35*I35*K35 -> 613470 | M35: 7898708518506 | N35: NÃO APLICA | O35: NÃO APLICA | P35: NÃO APLICA | Q35: 0.19 | R35: 0.03 | S35: 0.265 | T35: 1 | U35: 3917.40.90 | V35: 0 | W35: 17898708518503 | X35: 0.27 | Y35: 0.27 | Z35: 0.33 | AA35: =Y35*X35*Z35 -> 0.024057 | AB35: 20 | AC35: 27898708518500 | AD35: Validade indeterminada
B36: 100 | C36: TUBO PVC ESGOTO SEC. - 6M - DN 40 | D36: TUBOS PVC ESGOTO | E36: ESGOTO | F36: BR | G36: Amarrados | H36: 1.415 | I36: 6000 | J36: 40 | K36: 40 | L36: =J36*I36*K36 -> 9600000 | M36: 7897801304108 | N36: 0.0426 | O36: 6 | P36: 0.0426 | Q36: 0.17 | R36: 0.12 | S36: 6 | T36: 10 | U36: 3917.23.00 | V36: 0 | W36: 17897801304105 | X36: NÃO APLICA | Y36: NÃO APLICA | Z36: NÃO APLICA | AB36: 0 | AC36: 27897801304102 | AD36: Validade indeterminada
B37: 101 | C37: TUBO PVC ESGOTO PRIM. - 6M - DN 50 | D37: TUBOS PVC ESGOTO | E37: ESGOTO | F37: BR | G37: Amarrados | H37: 2.345 | I37: 6000 | J37: 50 | K37: 50 | L37: =J37*I37*K37 -> 15000000 | M37: 7897801304115 | N37: 0.062 | O37: 6 | P37: 0.062 | Q37: 0.24 | R37: 0.16 | S37: 6.002 | T37: 10 | U37: 3917.23.00 | V37: 0 | W37: 17897801304112 | X37: NÃO APLICA | Y37: NÃO APLICA | Z37: NÃO APLICA | AB37: 0 | AC37: 27897801304119 | AD37: Validade indeterminada
B38: 102 | C38: TUBO PVC ESGOTO PRIM. - 6M - DN 75 | D38: TUBOS PVC ESGOTO | E38: ESGOTO | F38: BR | G38: Amarrados | H38: 3.74 | I38: 6000 | J38: 75 | K38: 75 | L38: =J38*I38*K38 -> 33750000 | M38: 7897801304122 | N38: 0.0836 | O38: 6 | P38: 0.0836 | Q38: 0.25 | R38: 0.16 | S38: 6.002 | T38: 5 | U38: 3917.23.00 | V38: 0 | W38: 17897801304129 | X38: NÃO APLICA | Y38: NÃO APLICA | Z38: NÃO APLICA | AB38: 0 | AC38: 27897801304126 | AD38: Validade indeterminada
B39: 103 | C39: TUBO PVC ESGOTO PRIM. - 6M - DN 100 | D39: TUBOS PVC ESGOTO | E39: ESGOTO | F39: BR | G39: Amarrados | H39: 5.317 | I39: 6000 | J39: 101 | K39: 101 | L39: =J39*I39*K39 -> 61206000 | M39: 7897801304139 | N39: 0.1066 | O39: 6 | P39: 0.1066 | Q39: 0.335 | R39: 0.2 | S39: 6.002 | T39: 5 | U39: 3917.23.00 | V39: 0 | W39: 17897801304136 | X39: NÃO APLICA | Y39: NÃO APLICA | Z39: NÃO APLICA | AB39: 0 | AC39: 27897801304133 | AD39: Validade indeterminada
B40: 104 | C40: TUBO PVC ESGOTO PRIM. - 6M - DN 150 | D40: TUBOS PVC ESGOTO | E40: ESGOTO | F40: BR | G40: Amarrados | H40: 11.55 | I40: 6000 | J40: 150 | K40: 150 | L40: =J40*I40*K40 -> 135000000 | M40: 7897801304146 | N40: 0.155 | O40: 6 | P40: 0.155 | Q40: 0.1504 | R40: 0.1504 | S40: 6 | T40: 1 | U40: 3917.23.00 | V40: 0 | W40: 17897801304143 | X40: NÃO APLICA | Y40: NÃO APLICA | Z40: NÃO APLICA | AB40: 0 | AC40: 27897801304140 | AD40: Validade indeterminada
B41: 105 | C41: TUBO PVC ESGOTO PRIM. - 6M - DN 200 | D41: TUBOS PVC ESGOTO | E41: ESGOTO | F41: BR | G41: Amarrados | H41: 20.44 | I41: 6000 | J41: 200 | K41: 200 | L41: =J41*I41*K41 -> 240000000 | M41: 7897801308557 | N41: 0.208 | O41: 6 | P41: 0.208 | Q41: 0.2004 | R41: 0.2004 | S41: 6 | T41: 1 | U41: 3917.23.00 | V41: 0 | W41: 17897801308554 | X41: NÃO APLICA | Y41: NÃO APLICA | Z41: NÃO APLICA | AB41: 0 | AC41: 27897801308551 | AD41: Validade indeterminada
B42: 106 | C42: TUBO PVC LEVE - 6M - DN 250 | D42: TUBOS PVC ESGOTO | E42: ESGOTO | F42: BR | G42: Amarrados | H42: 20.77 | I42: 6000 | J42: 250 | K42: 250 | L42: =J42*I42*K42 -> 375000000 | M42: 7897801308571 | N42: 0.256 | O42: 6 | P42: 0.256 | Q42: 0.2504 | R42: 0.2504 | S42: 6 | T42: 1 | U42: 3917.23.00 | V42: 0 | W42: 17897801308578 | X42: NÃO APLICA | Y42: NÃO APLICA | Z42: NÃO APLICA | AB42: 0 | AC42: 27897801308575 | AD42: Validade indeterminada
B43: 110 | C43: TUBO PVC ESGOTO SEC. - 3M- DN 40 | D43: TUBOS PVC ESGOTO | E43: ESGOTO | F43: BR | G43: Amarrados | H43: 0.7055 | I43: 3000 | J43: 40 | K43: 40 | L43: =J43*I43*K43 -> 4800000 | M43: 7897801308625 | N43: 0.0402 | O43: 3 | P43: 0.0402 | Q43: 0.17 | R43: 0.12 | S43: 3 | T43: 10 | U43: 3917.23.00 | V43: 0 | W43: 17897801308622 | X43: NÃO APLICA | Y43: NÃO APLICA | Z43: NÃO APLICA | AB43: 0 | AC43: 27897801308629 | AD43: Validade indeterminada
B44: 111 | C44: TUBO PVC ESGOTO PRIM. - 3M- DN 50 | D44: TUBOS PVC ESGOTO | E44: ESGOTO | F44: BR | G44: Amarrados | H44: 1.185 | I44: 3000 | J44: 50 | K44: 50 | L44: =J44*I44*K44 -> 7500000 | M44: 7897801308632 | N44: 0.051 | O44: 3 | P44: 0.051 | Q44: 0.205 | R44: 0.14 | S44: 3.002 | T44: 10 | U44: 3917.23.00 | V44: 0 | W44: 17897801308639 | X44: NÃO APLICA | Y44: NÃO APLICA | Z44: NÃO APLICA | AB44: 0 | AC44: 27897801308636 | AD44: Validade indeterminada
B45: 112 | C45: TUBO PVC ESGOTO PRIM. - 3M- DN 75 | D45: TUBOS PVC ESGOTO | E45: ESGOTO | F45: BR | G45: Amarrados | H45: 1.855 | I45: 3000 | J45: 75 | K45: 75 | L45: =J45*I45*K45 -> 16875000 | M45: 7897801308649 | N45: 0.0759 | O45: 3 | P45: 0.0759 | Q45: 0.27 | R45: 0.16 | S45: 3.002 | T45: 5 | U45: 3917.23.00 | V45: 0 | W45: 17897801308646 | X45: NÃO APLICA | Y45: NÃO APLICA | Z45: NÃO APLICA | AB45: 0 | AC45: 27897801308643 | AD45: Validade indeterminada
B46: 113 | C46: TUBO PVC ESGOTO PRIM. - 3M- DN 100 | D46: TUBOS PVC ESGOTO | E46: ESGOTO | F46: BR | G46: Amarrados | H46: 2.658 | I46: 3000 | J46: 100 | K46: 100 | L46: =J46*I46*K46 -> 30000000 | M46: 7897801308656 | N46: 0.102 | O46: 3 | P46: 0.102 | Q46: 0.335 | R46: 0.2 | S46: 3.002 | T46: 5 | U46: 3917.23.00 | V46: 0 | W46: 17897801308653 | X46: NÃO APLICA | Y46: NÃO APLICA | Z46: NÃO APLICA | AB46: 0 | AC46: 27897801308650 | AD46: Validade indeterminada
B47: 114 | C47: TUBO PVC ESGOTO PRIM. - 3M- DN 150 | D47: TUBOS PVC ESGOTO | E47: ESGOTO | F47: BR | G47: Amarrados | H47: 5.82 | I47: 3000 | J47: 150 | K47: 150 | L47: =J47*I47*K47 -> 67500000 | M47: 7897801308663 | N47: 0.1504 | O47: 3.001 | P47: 0.1504 | Q47: 0.1504 | R47: 0.1504 | S47: 3.001 | T47: 1 | U47: 3917.23.00 | V47: 0 | W47: 17897801308660 | X47: NÃO APLICA | Y47: NÃO APLICA | Z47: NÃO APLICA | AB47: 0 | AC47: 27897801308667 | AD47: Validade indeterminada
...

Sheet DADOS NE_GO
H2: INDIVUDUAL (MM) | N2: Armazenamento (TUBOS) (M) | Q2: EMBALAGEM (M) | X2: Reembalagem (Master) (M)
B3: Produto | C3: Descrição | D3: Linha | E3: Família | F3: Unidade | G3: Tipo Embalagem | H3: Peso Bruto (produto + embalagem) | I3: Comprimento | J3: Altura | K3: Largura | L3: Cubagem | M3: Código de Barras | N3: Altur.Armaze | O3: Compr.Armaze | P3: Largu.Armaze | Q3: Larg.Emb | R3: Alt.Emb | S3: Compr.Emb | T3: Quantidade Embalagem | U3: Pos.IPI/NCM | V3: Aliq. IPI | W3: Código de Barras | X3: Larg.Reemb | Y3: Alt.Reemb | Z3: Compr.Reemb | AA3: Cubagem | AB3: Quantidade | AC3: Código de Barras | AD3: Data de validade
B4: 23 | C4: TUBO PVC SOLDAVEL - 6M - 20MM | D4: TUBOS PVC SOLDAVEL | E4: AF | F4: BR | G4: Amarrados | H4: 0.82 | I4: 6000 | J4: 20 | K4: 20 | L4: =J4*I4*K4 -> 2400000 | M4: 7897801304009 | N4: 0.023 | O4: 6 | P4: 0.023 | Q4: 0.085 | R4: 0.085 | S4: 6 | T4: 12 | U4: 3917.23.00 | V4: 0 | W4: 17897801304006 | X4: NÃO APLICA | Y4: NÃO APLICA | Z4: NÃO APLICA | AB4: 0 | AC4: 27897801304003 | AD4: Validade indeterminada
B5: 24 | C5: TUBO PVC SOLDAVEL - 6M - 25MM | D5: TUBOS PVC SOLDAVEL | E5: AF | F5: BR | G5: Amarrados | H5: 1.172 | I5: 6000 | J5: 25 | K5: 25 | L5: =J5*I5*K5 -> 3750000 | M5: 7897801304016 | N5: 0.027 | O5: 6 | P5: 0.027 | Q5: 0.085 | R5: 0.085 | S5: 6 | T5: 8 | U5: 3917.23.00 | V5: 0 | W5: 17897801304013 | X5: NÃO APLICA | Y5: NÃO APLICA | Z5: NÃO APLICA | AB5: 0 | AC5: 27897801304010 | AD5: Validade indeterminada
B6: 25 | C6: TUBO PVC SOLDAVEL - 6M - 32MM | D6: TUBOS PVC SOLDAVEL | E6: AF | F6: BR | G6: Amarrados | H6: 1.845 | I6: 6000 | J6: 32 | K6: 32 | L6: =J6*I6*K6 -> 6144000 | M6: 7897801304023 | N6: 0.035 | O6: 6 | P6: 0.035 | Q6: 0.13 | R6: 0.09 | S6: 6 | T6: 10 | U6: 3917.23.00 | V6: 0 | W6: 17897801304020 | X6: NÃO APLICA | Y6: NÃO APLICA | Z6: NÃO APLICA | AB6: 0 | AC6: 27897801304027 | AD6: Validade indeterminada
B7: 26 | C7: TUBO PVC SOLDAVEL - 6M - 40MM | D7: TUBOS PVC SOLDAVEL | E7: AF | F7: BR | G7: Amarrados | H7: 2.645 | I7: 6000 | J7: 40 | K7: 40 | L7: =J7*I7*K7 -> 9600000 | M7: 7897801304030 | N7: 0.045 | O7: 6 | P7: 0.045 | Q7: 0.12 | R7: 0.075 | S7: 6 | T7: 5 | U7: 3917.23.00 | V7: 0 | W7: 17897801304037 | X7: NÃO APLICA | Y7: NÃO APLICA | Z7: NÃO APLICA | AB7: 0 | AC7: 27897801304034 | AD7: Validade indeterminada
B8: 27 | C8: TUBO PVC SOLDAVEL - 6M - 50MM | D8: TUBOS PVC SOLDAVEL | E8: AF | F8: BR | G8: Amarrados | H8: 4.122 | I8: 6000 | J8: 50 | K8: 50 | L8: =J8*I8*K8 -> 15000000 | M8: 7897801304047 | N8: 0.055 | O8: 6 | P8: 0.055 | Q8: 0.17 | R8: 0.11 | S8: 6 | T8: 5 | U8: 3917.23.00 | V8: 0 | W8: 17897801304044 | X8: NÃO APLICA | Y8: NÃO APLICA | Z8: NÃO APLICA | AB8: 0 | AC8: 27897801304041 | AD8: Validade indeterminada
B9: 28 | C9: TUBO PVC SOLDAVEL - 6M - 60MM | D9: TUBOS PVC SOLDAVEL | E9: AF | F9: BR | G9: Amarrados | H9: 5.382 | I9: 6000 | J9: 60 | K9: 60 | L9: =J9*I9*K9 -> 21600000 | M9: 7897801304054 | N9: 0.067 | O9: 6 | P9: 0.067 | Q9: 0.125 | R9: 0.12 | S9: 6 | T9: 3 | U9: 3917.23.00 | V9: 0 | W9: 17897801304051 | X9: NÃO APLICA | Y9: NÃO APLICA | Z9: NÃO APLICA | AB9: 0 | AC9: 27897801304058 | AD9: Validade indeterminada
B10: 29 | C10: TUBO PVC SOLDAVEL - 6M - 75MM | D10: TUBOS PVC SOLDAVEL | E10: AF | F10: BR | G10: Amarrados | H10: 8.53 | I10: 6000 | J10: 75 | K10: 75 | L10: =J10*I10*K10 -> 33750000 | M10: 7897801308564 | N10: 0.083 | O10: 6 | P10: 0.083 | Q10: 0.0752 | R10: 0.0752 | S10: 6 | T10: 1 | U10: 3917.23.00 | V10: 0 | W10: 17897801308561 | X10: NÃO APLICA | Y10: NÃO APLICA | Z10: NÃO APLICA | AB10: 0 | AC10: 27897801308568 | AD10: Validade indeterminada
B11: 30 | C11: TUBO PVC SOLDAVEL - 6M - 85MM | D11: TUBOS PVC SOLDAVEL | E11: AF | F11: BR | G11: Amarrados | H11: 10.85 | I11: 6000 | J11: 85 | K11: 85 | L11: =J11*I11*K11 -> 43350000 | M11: 7897801308588 | N11: 0.095 | O11: 6 | P11: 0.095 | Q11: 0.0852 | R11: 0.0852 | S11: 6 | T11: 1 | U11: 3917.23.00 | V11: 0 | W11: 17897801308585 | X11: NÃO APLICA | Y11: NÃO APLICA | Z11: NÃO APLICA | AB11: 0 | AC11: 27897801308582 | AD11: Validade indeterminada
B12: 31 | C12: TUBO PVC SOLDAVEL - 6M - 110MM | D12: TUBOS PVC SOLDAVEL | E12: AF | F12: BR | G12: Amarrados | H12: 18.25 | I12: 6000 | J12: 110 | K12: 110 | L12: =J12*I12*K12 -> 72600000 | M12: 7897801308595 | N12: 0.122 | O12: 6 | P12: 0.122 | Q12: 0.1102 | R12: 0.1102 | S12: 6 | T12: 1 | U12: 3917.23.00 | V12: 0 | W12: 17897801308592 | X12: NÃO APLICA | Y12: NÃO APLICA | Z12: NÃO APLICA | AB12: 0 | AC12: 27897801308599 | AD12: Validade indeterminada
B13: 32 | C13: TUBO PVC SOLDAVEL - 3M - 20MM | D13: TUBOS PVC SOLDAVEL | E13: AF | F13: BR | G13: Amarrados | H13: 0.42 | I13: 3000 | J13: 20 | K13: 20 | L13: =J13*I13*K13 -> 1200000 | M13: 7897801304306 | N13: 0.0202 | O13: 3 | P13: 0.0202 | Q13: 0.085 | R13: 0.085 | S13: 3 | T13: 12 | U13: 3917.23.00 | V13: 0 | W13: 17897801304303 | X13: NÃO APLICA | Y13: NÃO APLICA | Z13: NÃO APLICA | AB13: 0 | AC13: 27897801304300 | AD13: Validade indeterminada
B14: 33 | C14: TUBO PVC SOLDAVEL - 3M - 25MM | D14: TUBOS PVC SOLDAVEL | E14: AF | F14: BR | G14: Amarrados | H14: 0.579 | I14: 3000 | J14: 25 | K14: 25 | L14: =J14*I14*K14 -> 1875000 | M14: 7897801304313 | N14: 0.0252 | O14: 3 | P14: 0.0252 | Q14: 0.1 | R14: 0.09 | S14: 3 | T14: 8 | U14: 3917.23.00 | V14: 0 | W14: 17897801304310 | X14: NÃO APLICA | Y14: NÃO APLICA | Z14: NÃO APLICA | AB14: 0 | AC14: 27897801304317 | AD14: Validade indeterminada
B15: 34 | C15: TUBO PVC SOLDAVEL - 3M - 32MM | D15: TUBOS PVC SOLDAVEL | E15: AF | F15: BR | G15: Amarrados | H15: 0.925 | I15: 3000 | J15: 32 | K15: 32 | L15: =J15*I15*K15 -> 3072000 | M15: 7897801308991 | N15: 0.0322 | O15: 3 | P15: 0.0322 | Q15: 0.13 | R15: 0.09 | S15: 3 | T15: 10 | U15: 3917.23.00 | V15: 0 | W15: 17897801308998 | X15: NÃO APLICA | Y15: NÃO APLICA | Z15: NÃO APLICA | AB15: 0 | AC15: 27897801308995 | AD15: Validade indeterminada
... B22: 52 | C22: TUBO ULTRATERM 3M - 28MM | D22: CPVC - ULTRATERM - TUBOS | E22: AQ | F22: BR | G22: Amarrados | H22: 0.95 | I22: 3000 | J22: 28 | K22: 28 | L22: =J22*I22*K22 -> 2352000 | M22: 7897801320283 | N22: 0.028 | O22: 3 | P22: 0.028 | Q22: 0.028 | R22: 3 | S22: 0.028 | T22: 10 | U22: 3917.23.00 | V22: 0 | W22: 17897801320280 | X22: NÃO APLICA | Y22: NÃO APLICA | Z22: NÃO APLICA | AB22: 0 | AC22: 27897801320287 | AD22: Validade indeterminada
B23: 78 | C23: RALO QUADRADO OCULTO 10x10 cm KRONA | D23: CAIXAS E RALOS | E23: ESGOTO | F23: PC | G23: Blister | H23: 0.715 | I23: 125 | J23: 48 | K23: 125 | L23: 750000 | M23: 7898708518384 | N23: NÃO APLICA | O23: NÃO APLICA | P23: NÃO APLICA | Q23: 0.1 | R23: 0.024 | S23: 0.1 | T23: 1 | U23: 3917.40.90 | V23: 0 | W23: 17898708518381 | X23: 0.066 | Y23: 0.25 | Z23: 0.165 | AA23: 0.0027225 | AB23: 20 | AC23: 27898708518388 | AD23: Validade indeterminada
B24: 79 | C24: RALO QUADRADO OCULTO 15x15 cm KRONA | D24: CAIXAS E RALOS | E24: ESGOTO | F24: PC | G24: Blister | H24: 1.083 | I24: 195 | J24: 39 | K24: 195 | L24: 1482975 | M24: 7898708518391 | N24: NÃO APLICA | O24: NÃO APLICA | P24: NÃO APLICA | Q24: 0.152 | R24: 0.02 | S24: 0.152 | T24: 1 | U24: 3917.40.90 | V24: 0 | W24: 17898708518398 | X24: 0.045 | Y24: 0.222 | Z24: 0.223 | AA24: 0.00222777 | AB24: 45 | AC24: 27898708518395 | AD24: Validade indeterminada
B25: 80 | C25: RALO LINEAR PVC SECO 50CM OCULTO KRONA | D25: CAIXAS E RALOS | E25: ESGOTO | F25: PC | G25: Filme | H25: 0.696 | I25: 523 | J25: 25 | K25: 100 | L25: 1307500 | M25: 7898708518407 | N25: NÃO APLICA | O25: NÃO APLICA | P25: NÃO APLICA | Q25: 0.076 | R25: 0.012 | S25: 0.248 | T25: 1 | U25: 3917.40.90 | V25: 0 | W25: 17898708518404 | X25: 0.105 | Y25: 0.075 | Z25: 0.53 | AA25: 0.00417375 | AB25: 30 | AC25: 27898708518401 | AD25: Validade indeterminada
B26: 81 | C26: RALO LINEAR PVC SECO 50CM ACAB. POLIDO KRONA | D26: CAIXAS E RALOS | E26: ESGOTO | F26: PC | G26: Caixa | H26: 0.514 | I26: 523 | J26: 25 | K26: 100 | L26: 1307500 | M26: 7898708518414 | N26: NÃO APLICA | O26: NÃO APLICA | P26: NÃO APLICA | Q26: 0.076 | R26: 0.026 | S26: 0.248 | T26: 1 | U26: 3917.40.90 | V26: 0 | W26: 17898708518411 | X26: 0.105 | Y26: 0.075 | Z26: 0.53 | AA26: 0.00417375 | AB26: 24 | AC26: 27898708518418 | AD26: Validade indeterminada
B27: 82 | C27: RALO LINEAR PVC SIFONADO 50CM OCULTO KRONA | D27: CAIXAS E RALOS | E27: ESGOTO | F27: PC | G27: Filme | H27: 1.064 | I27: 523 | J27: 25 | K27: 100 | L27: 1307500 | M27: 7898708518421 | N27: NÃO APLICA | O27: NÃO APLICA | P27: NÃO APLICA | Q27: 0.076 | R27: 0.012 | S27: 0.248 | T27: 1 | U27: 3917.40.90 | V27: 0 | W27: 17898708518428 | X27: 0.105 | Y27: 0.075 | Z27: 0.53 | AA27: 0.00417375 | AB27: 30 | AC27: 27898708518425 | AD27: Validade indeterminada
B28: 83 | C28: RALO LINEAR PVC SIFONADO 50CM ACAB. POLIDO KRONA | D28: CAIXAS E RALOS | E28: ESGOTO | F28: PC | G28: Caixa | H28: 0.729 | I28: 523 | J28: 25 | K28: 100 | L28: 1307500 | M28: 7898708518438 | N28: NÃO APLICA | O28: NÃO APLICA | P28: NÃO APLICA | Q28: 0.076 | R28: 0.026 | S28: 0.248 | T28: 1 | U28: 3917.40.90 | V28: 0 | W28: 17898708518435 | X28: 0.105 | Y28: 0.075 | Z28: 0.53 | AA28: 0.00417375 | AB28: 24 | AC28: 27898708518432 | AD28: Validade indeterminada
B29: 84 | C29: RALO LINEAR PVC SECO 75CM SAIDA CENTRAL OCULTO KRONA | D29: CAIXAS E RALOS | E29: ESGOTO | F29: PC | G29: Filme | H29: 0.495 | I29: 773 | J29: 33 | K29: 100 | L29: 2550900 | M29: 7898708518445 | N29: NÃO APLICA | O29: NÃO APLICA | P29: NÃO APLICA | Q29: 0.076 | R29: 0.012 | S29: 0.248 | T29: 1 | U29: 3917.40.90 | V29: 0 | W29: 17898708518442 | X29: 0.105 | Y29: 0.075 | Z29: 0.775 | AA29: 0.006103125 | AB29: 20 | AC29: 27898708518449 | AD29: Validade indeterminada
B30: 85 | C30: RALO LINEAR PVC SECO 75CM SAIDA CENTRAL POLIDO KRONA | D30: CAIXAS E RALOS | E30: ESGOTO | F30: PC | G30: Caixa | H30: 0.197 | I30: 773 | J30: 33 | K30: 100 | L30: 2550900 | M30: 7898708518452 | N30: NÃO APLICA | O30: NÃO APLICA | P30: NÃO APLICA | Q30: 0.076 | R30: 0.026 | S30: 0.748 | T30: 1 | U30: 3917.40.90 | V30: 0 | W30: 17898708518459 | X30: 0.105 | Y30: 0.075 | Z30: 0.775 | AA30: 0.006103125 | AB30: 18 | AC30: 27898708518456 | AD30: Validade indeterminada
B31: 86 | C31: RALO LINEAR PVC SIFONADO 75CM SAIDA CENTRAL OCULTO KRONA | D31: CAIXAS E RALOS | E31: ESGOTO | F31: PC | G31: Filme | H31: 0.71 | I31: 773 | J31: 33 | K31: 100 | L31: 2550900 | M31: 7898708518469 | N31: NÃO APLICA | O31: NÃO APLICA | P31: NÃO APLICA | Q31: 0.076 | R31: 0.012 | S31: 0.248 | T31: 1 | U31: 3917.40.90 | V31: 0 | W31: 17898708518466 | X31: 0.105 | Y31: 0.075 | Z31: 0.775 | AA31: 0.006103125 | AB31: 20 | AC31: 27898708518463 | AD31: Validade indeterminada
B32: 87 | C32: RALO LINEAR PVC SIFONADO 75CM SAIDA CENTRAL POLIDO KRONA | D32: CAIXAS E RALOS | E32: ESGOTO | F32: PC | G32: Caixa | H32: 0.424 | I32: 773 | J32: 33 | K32: 100 | L32: 2550900 | M32: 7898708518476 | N32: NÃO APLICA | O32: NÃO APLICA | P32: NÃO APLICA | Q32: 0.076 | R32: 0.026 | S32: 0.748 | T32: 1 | U32: 3917.40.90 | V32: 0 | W32: 17898708518473 | X32: 0.105 | Y32: 0.075 | Z32: 0.775 | AA32: 0.006103125 | AB32: 18 | AC32: 27898708518470 | AD32: Validade indeterminada
B33: 88 | C33: SIFAO 50MM PARA RALOS KRONA | D33: CAIXAS E RALOS | E33: ESGOTO | F33: PC | G33: Blister | H33: 0.059 | I33: 50 | J33: 80 | K33: 50 | L33: 200000 | M33: 7898708518483 | N33: NÃO APLICA | O33: NÃO APLICA | P33: NÃO APLICA | Q33: 0.054 | R33: 0.185 | S33: 0.131 | T33: 1 | U33: 3917.40.90 | V33: 0 | W33: 17898708518480 | X33: 0.27 | Y33: 0.27 | Z33: 0.33 | AA33: 0.024057 | AB33: 20 | AC33: 27898708518487 | AD33: Validade indeterminada
B34: 89 | C34: BOLSA ACOPLAVEL CX SIFONADA 100MM PVC | D34: CAIXAS E RALOS | E34: ESGOTO | F34: PC | G34: Sacos | H34: 0.056 | I34: 95 | J34: 30 | K34: 95 | L34: 270750 | M34: 7898708518490 | N34: NÃO APLICA | O34: NÃO APLICA | P34: NÃO APLICA | Q34: 0.19 | R34: 0.03 | S34: 0.265 | T34: 1 | U34: 3917.40.90 | V34: 0 | W34: 17898708518497 | X34: 0.27 | Y34: 0.27 | Z34: 0.33 | AA34: 0.024057 | AB34: 20 | AC34: 27898708518494 | AD34: Validade indeterminada
B35: 90 | C35: BOLSA ACOPLAVEL CX SIFONADA 150MM PVC | D35: CAIXAS E RALOS | E35: ESGOTO | F35: PC | G35: Sacos | H35: 0.092 | I35: 143 | J35: 30 | K35: 143 | L35: 613470 | M35: 7898708518506 | N35: NÃO APLICA | O35: NÃO APLICA | P35: NÃO APLICA | Q35: 0.19 | R35: 0.03 | S35: 0.265 | T35: 1 | U35: 3917.40.90 | V35: 0 | W35: 17898708518503 | X35: 0.27 | Y35: 0.27 | Z35: 0.33 | AA35: 0.024057 | AB35: 20 | AC35: 27898708518500 | AD35: Validade indeterminada
B36: 100 | C36: TUBO PVC ESGOTO SEC. - 6M - DN 40 | D36: TUBOS PVC ESGOTO | E36: ESGOTO | F36: BR | G36: Amarrados | H36: 1.415 | I36: 6000 | J36: 40 | K36: 40 | L36: =J36*I36*K36 -> 9600000 | M36: 7897801304108 | N36: 0.0426 | O36: 6 | P36: 0.0426 | Q36: 0.17 | R36: 0.12 | S36: 6 | T36: 10 | U36: 3917.23.00 | V36: 0 | W36: 17897801304105 | X36: NÃO APLICA | Y36: NÃO APLICA | Z36: NÃO APLICA | AB36: 0 | AC36: 27897801304102 | AD36: Validade indeterminada
B37: 101 | C37: TUBO PVC ESGOTO PRIM. - 6M - DN 50 | D37: TUBOS PVC ESGOTO | E37: ESGOTO | F37: BR | G37: Amarrados | H37: 2.345 | I37: 6000 | J37: 50 | K37: 50 | L37: =J37*I37*K37 -> 15000000 | M37: 7897801304115 | N37: 0.062 | O37: 6 | P37: 0.062 | Q37: 0.24 | R37: 0.16 | S37: 6.002 | T37: 10 | U37: 3917.23.00 | V37: 0 | W37: 17897801304112 | X37: NÃO APLICA | Y37: NÃO APLICA | Z37: NÃO APLICA | AB37: 0 | AC37: 27897801304119 | AD37: Validade indeterminada
B38: 102 | C38: TUBO PVC ESGOTO PRIM. - 6M - DN 75 | D38: TUBOS PVC ESGOTO | E38: ESGOTO | F38: BR | G38: Amarrados | H38: 3.74 | I38: 6000 | J38: 75 | K38: 75 | L38: =J38*I38*K38 -> 33750000 | M38: 7897801304122 | N38: 0.0836 | O38: 6 | P38: 0.0836 | Q38: 0.25 | R38: 0.16 | S38: 6.002 | T38: 5 | U38: 3917.23.00 | V38: 0 | W38: 17897801304129 | X38: NÃO APLICA | Y38: NÃO APLICA | Z38: NÃO APLICA | AB38: 0 | AC38: 27897801304126 | AD38: Validade indeterminada
B39: 103 | C39: TUBO PVC ESGOTO PRIM. - 6M - DN 100 | D39: TUBOS PVC ESGOTO | E39: ESGOTO | F39: BR | G39: Amarrados | H39: 5.317 | I39: 6000 | J39: 101 | K39: 101 | L39: =J39*I39*K39 -> 61206000 | M39: 7897801304139 | N39: 0.1066 | O39: 6 | P39: 0.1066 | Q39: 0.335 | R39: 0.2 | S39: 6.002 | T39: 5 | U39: 3917.23.00 | V39: 0 | W39: 17897801304136 | X39: NÃO APLICA | Y39: NÃO APLICA | Z39: NÃO APLICA | AB39: 0 | AC39: 27897801304133 | AD39: Validade indeterminada
B40: 104 | C40: TUBO PVC ESGOTO PRIM. - 6M - DN 150 | D40: TUBOS PVC ESGOTO | E40: ESGOTO | F40: BR | G40: Amarrados | H40: 11.55 | I40: 6000 | J40: 150 | K40: 150 | L40: =J40*I40*K40 -> 135000000 | M40: 7897801304146 | N40: 0.155 | O40: 6 | P40: 0.155 | Q40: 0.1504 | R40: 0.1504 | S40: 6 | T40: 1 | U40: 3917.23.00 | V40: 0 | W40: 17897801304143 | X40: NÃO APLICA | Y40: NÃO APLICA | Z40: NÃO APLICA | AB40: 0 | AC40: 27897801304140 | AD40: Validade indeterminada
B41: 105 | C41: TUBO PVC ESGOTO PRIM. - 6M - DN 200 | D41: TUBOS PVC ESGOTO | E41: ESGOTO | F41: BR | G41: Amarrados | H41: 20.44 | I41: 6000 | J41: 200 | K41: 200 | L41: =J41*I41*K41 -> 240000000 | M41: 7897801308557 | N41: 0.208 | O41: 6 | P41: 0.208 | Q41: 0.2004 | R41: 0.2004 | S41: 6 | T41: 1 | U41: 3917.23.00 | V41: 0 | W41: 17897801308554 | X41: NÃO APLICA | Y41: NÃO APLICA | Z41: NÃO APLICA | AB41: 0 | AC41: 27897801308551 | AD41: Validade indeterminada
B42: 106 | C42: TUBO PVC LEVE - 6M - DN 250 | D42: TUBOS PVC ESGOTO | E42: ESGOTO | F42: BR | G42: Amarrados | H42: 20.77 | I42: 6000 | J42: 250 | K42: 250 | L42: =J42*I42*K42 -> 375000000 | M42: 7897801308571 | N42: 0.256 | O42: 6 | P42: 0.256 | Q42: 0.2504 | R42: 0.2504 | S42: 6 | T42: 1 | U42: 3917.23.00 | V42: 0 | W42: 17897801308578 | X42: NÃO APLICA | Y42: NÃO APLICA | Z42: NÃO APLICA | AB42: 0 | AC42: 27897801308575 | AD42: Validade indeterminada
B43: 110 | C43: TUBO PVC ESGOTO SEC. - 3M- DN 40 | D43: TUBOS PVC ESGOTO | E43: ESGOTO | F43: BR | G43: Amarrados | H43: 0.7055 | I43: 3000 | J43: 40 | K43: 40 | L43: =J43*I43*K43 -> 4800000 | M43: 7897801308625 | N43: 0.0402 | O43: 3 | P43: 0.0402 | Q43: 0.17 | R43: 0.12 | S43: 3 | T43: 10 | U43: 3917.23.00 | V43: 0 | W43: 17897801308622 | X43: NÃO APLICA | Y43: NÃO APLICA | Z43: NÃO APLICA | AB43: 0 | AC43: 27897801308629 | AD43: Validade indeterminada
B44: 111 | C44: TUBO PVC ESGOTO PRIM. - 3M- DN 50 | D44: TUBOS PVC ESGOTO | E44: ESGOTO | F44: BR | G44: Amarrados | H44: 1.185 | I44: 3000 | J44: 50 | K44: 50 | L44: =J44*I44*K44 -> 7500000 | M44: 7897801308632 | N44: 0.051 | O44: 3 | P44: 0.051 | Q44: 0.205 | R44: 0.14 | S44: 3.002 | T44: 10 | U44: 3917.23.00 | V44: 0 | W44: 17897801308639 | X44: NÃO APLICA | Y44: NÃO APLICA | Z44: NÃO APLICA | AB44: 0 | AC44: 27897801308636 | AD44: Validade indeterminada
B45: 112 | C45: TUBO PVC ESGOTO PRIM. - 3M- DN 75 | D45: TUBOS PVC ESGOTO | E45: ESGOTO | F45: BR | G45: Amarrados | H45: 1.855 | I45: 3000 | J45: 75 | K45: 75 | L45: =J45*I45*K45 -> 16875000 | M45: 7897801308649 | N45: 0.0759 | O45: 3 | P45: 0.0759 | Q45: 0.27 | R45: 0.16 | S45: 3.002 | T45: 5 | U45: 3917.23.00 | V45: 0 | W45: 17897801308646 | X45: NÃO APLICA | Y45: NÃO APLICA | Z45: NÃO APLICA | AB45: 0 | AC45: 27897801308643 | AD45: Validade indeterminada
B46: 113 | C46: TUBO PVC ESGOTO PRIM. - 3M- DN 100 | D46: TUBOS PVC ESGOTO | E46: ESGOTO | F46: BR | G46: Amarrados | H46: 2.658 | I46: 3000 | J46: 100 | K46: 100 | L46: =J46*I46*K46 -> 30000000 | M46: 7897801308656 | N46: 0.102 | O46: 3 | P46: 0.102 | Q46: 0.335 | R46: 0.2 | S46: 3.002 | T46: 5 | U46: 3917.23.00 | V46: 0 | W46: 17897801308653 | X46: NÃO APLICA | Y46: NÃO APLICA | Z46: NÃO APLICA | AB46: 0 | AC46: 27897801308650 | AD46: Validade indeterminada
B47: 114 | C47: TUBO PVC ESGOTO PRIM. - 3M- DN 150 | D47: TUBOS PVC ESGOTO | E47: ESGOTO | F47: BR | G47: Amarrados | H47: 5.82 | I47: 3000 | J47: 150 | K47: 150 | L47: =J47*I47*K47 -> 67500000 | M47: 7897801308663 | N47: 0.1504 | O47: 3.001 | P47: 0.1504 | Q47: 0.1504 | R47: 0.1504 | S47: 3.001 | T47: 1 | U47: 3917.23.00 | V47: 0 | W47: 17897801308660 | X47: NÃO APLICA | Y47: NÃO APLICA | Z47: NÃO APLICA | AB47: 0 | AC47: 27897801308667 | AD47: Validade indeterminada
...

Sheet informações de produtos
B2: Produto | C2: Descrição | D2: Linha | E2: Função | F2: Aplicação | G2: Características técnicas | H2: Normas de referência | I2: Benefícios
B3: 23 | C3: TUBO PVC SOLDAVEL - 6M - 20MM | D3: TUBOS PVC SOLDAVEL
B4: 24 | C4: TUBO PVC SOLDAVEL - 6M - 25MM | D4: TUBOS PVC SOLDAVEL
B5: 25 | C5: TUBO PVC SOLDAVEL - 6M - 32MM | D5: TUBOS PVC SOLDAVEL
B6: 26 | C6: TUBO PVC SOLDAVEL - 6M - 40MM | D6: TUBOS PVC SOLDAVEL
B7: 27 | C7: TUBO PVC SOLDAVEL - 6M - 50MM | D7: TUBOS PVC SOLDAVEL
B8: 28 | C8: TUBO PVC SOLDAVEL - 6M - 60MM | D8: TUBOS PVC SOLDAVEL
B9: 29 | C9: TUBO PVC SOLDAVEL - 6M - 75MM | D9: TUBOS PVC SOLDAVEL
B10: 30 | C10: TUBO PVC SOLDAVEL - 6M - 85MM | D10: TUBOS PVC SOLDAVEL
B11: 31 | C11: TUBO PVC SOLDAVEL - 6M - 110MM | D11: TUBOS PVC SOLDAVEL
B12: 32 | C12: TUBO PVC SOLDAVEL - 3M - 20MM | D12: TUBOS PVC SOLDAVEL
B13: 33 | C13: TUBO PVC SOLDAVEL - 3M - 25MM | D13: TUBOS PVC SOLDAVEL
B14: 34 | C14: TUBO PVC SOLDAVEL - 3M - 32MM | D14: TUBOS PVC SOLDAVEL
... B18: 38 | C18: TUBO PVC SOLDAVEL - 3M - 75MM | D18: TUBOS PVC SOLDAVEL
B19: 50 | C19: TUBO ULTRATERM 3M - 15MM | D19: CPVC - ULTRATERM - TUBOS | E19: Conduzir por longos trechos o fluido em elevadas temperaturas ou pressões sem comprometer a instalação e suas propriedades. | F19: Utilizada em instalação hidráulica residencial, comercial e industrial na geração de água quente ou sistemas de água fria com alta pressão, Por exemplo: Ramais de água quente, linhas de prumada de água fria. | G19: *Material: CPVC (Policloreto de Vinila Clorado). *Processo: Extrusão * Cor: Bege *Conexão: Ponta / Ponta *Temperatura x Pressão: *20 ͦC x 24 kgf/cm² *70 ͦC x 9 kgf/cm² | H19: *ABNT NBR 15884 *ABNT NBR 5626 | I19: *Sem efeito nocivo ao organismo, atóxico. *Baixa condutividade térmica, isolante. * Resistente a corrosão, não enferruja. *Superfície interna lisa, não incrusta.
B20: 51 | C20: TUBO ULTRATERM 3M - 22MM | D20: CPVC - ULTRATERM - TUBOS | E20: Conduzir por longos trechos o fluido em elevadas temperaturas ou pressões sem comprometer a instalação e suas propriedades. | F20: Utilizada em instalação hidráulica residencial, comercial e industrial na geração de água quente ou sistemas de água fria com alta pressão, Por exemplo: Ramais de água quente, linhas de prumada de água fria. | G20: *Material: CPVC (Policloreto de Vinila Clorado). *Processo: Extrusão * Cor: Bege *Conexão: Ponta / Ponta *Temperatura x Pressão: *20 ͦC x 24 kgf/cm² *70 ͦC x 9 kgf/cm² | H20: *ABNT NBR 15884 *ABNT NBR 5626 | I20: *Sem efeito nocivo ao organismo, atóxico. *Baixa condutividade térmica, isolante. * Resistente a corrosão, não enferruja. *Superfície interna lisa, não incrusta.
B21: 52 | C21: TUBO ULTRATERM 3M - 28MM | D21: CPVC - ULTRATERM - TUBOS | E21: Conduzir por longos trechos o fluido em elevadas temperaturas ou pressões sem comprometer a instalação e suas propriedades. | F21: Utilizada em instalação hidráulica residencial, comercial e industrial na geração de água quente ou sistemas de água fria com alta pressão, Por exemplo: Ramais de água quente, linhas de prumada de água fria. | G21: *Material: CPVC (Policloreto de Vinila Clorado). *Processo: Extrusão * Cor: Bege *Conexão: Ponta / Ponta *Temperatura x Pressão: *20 ͦC x 24 kgf/cm² *70 ͦC x 9 kgf/cm² | H21: *ABNT NBR 15884 *ABNT NBR 5626 | I21: *Sem efeito nocivo ao organismo, atóxico. *Baixa condutividade térmica, isolante. * Resistente a corrosão, não enferruja. *Superfície interna lisa, não incrusta.
B22: 100 | C22: TUBO PVC ESGOTO SEC. - 6M - DN 40 | D22: TUBOS PVC ESGOTO
B23: 101 | C23: TUBO PVC ESGOTO PRIM. - 6M - DN 50 | D23: TUBOS PVC ESGOTO
B24: 102 | C24: TUBO PVC ESGOTO PRIM. - 6M - DN 75 | D24: TUBOS PVC ESGOTO
B25: 103 | C25: TUBO PVC ESGOTO PRIM. - 6M - DN 100 | D25: TUBOS PVC ESGOTO
B26: 104 | C26: TUBO PVC ESGOTO PRIM. - 6M - DN 150 | D26: TUBOS PVC ESGOTO
B27: 105 | C27: TUBO PVC ESGOTO PRIM. - 6M - DN 200 | D27: TUBOS PVC ESGOTO
B28: 106 | C28: TUBO PVC LEVE - 6M - DN 250 | D28: TUBOS PVC ESGOTO
B29: 110 | C29: TUBO PVC ESGOTO SEC. - 3M- DN 40 | D29: TUBOS PVC ESGOTO
B30: 111 | C30: TUBO PVC ESGOTO PRIM. - 3M- DN 50 | D30: TUBOS PVC ESGOTO
B31: 112 | C31: TUBO PVC ESGOTO PRIM. - 3M- DN 75 | D31: TUBOS PVC ESGOTO
B32: 113 | C32: TUBO PVC ESGOTO PRIM. - 3M- DN 100 | D32: TUBOS PVC ESGOTO
B33: 114 | C33: TUBO PVC ESGOTO PRIM. - 3M- DN 150 | D33: TUBOS PVC ESGOTO
... B41: 122 | C41: TUBO PVC ROSC 2 | D41: TUBOS PVC BRANCO
B42: 136 | C42: TUBO PVC ESG SR 6M DN50X6M | D42: TUBOS PVC ESGOTO | E42: Instalações prediais industriais, comerciais e residenciais, principalmente quando se exige maiores esforços. | F42: A linha de Esgoto Série Reforçada é utilizada em instalações prediais de esgoto sanitário, água pluvial e ventilação na qual se necessita de uma maior classe de rigidez. Geralmente utilizada em obras verticais com mais de três pavimentos, como: tubos de queda e subcoletores. | G42: *Matéria Prima PVC (Policloreto de Vinila) *Cor: Cinza Claro *Processo: Extrusão *Temperatura Nominal: 75 ͦC (regime não contínuo) *Escoamento por gravidade, não submetida a pressão e ventilação. *Resistência a classe de rigidez de 3.200Pa para os tubos esgoto DN 100 e 150 mm. | H42: *ABNT NBR 5688 *ABNT NBR 8160 | I42: *Resistente a esforços mecânicos e a temperatura. *Fácil instalação. *Simples execução das juntas, leveza dos materiais. *Estanqueidade em junta elástica. *Bolsa com dupla ação: junta elástica e soldável.
B43: 137 | C43: TUBO PVC ESG SR 6M DN75X6M | D43: TUBOS PVC ESGOTO | E43: Instalações prediais industriais, comerciais e residenciais, principalmente quando se exige maiores esforços. | F43: A linha de Esgoto Série Reforçada é utilizada em instalações prediais de esgoto sanitário, água pluvial e ventilação na qual se necessita de uma maior classe de rigidez. Geralmente utilizada em obras verticais com mais de três pavimentos, como: tubos de queda e subcoletores. | G43: *Matéria Prima PVC (Policloreto de Vinila) *Cor: Cinza Claro *Processo: Extrusão *Temperatura Nominal: 75 ͦC (regime não contínuo) *Escoamento por gravidade, não submetida a pressão e ventilação. *Resistência a classe de rigidez de 3.200Pa para os tubos esgoto DN 100 e 150 mm. | H43: *ABNT NBR 5688 *ABNT NBR 8160 | I43: *Resistente a esforços mecânicos e a temperatura. *Fácil instalação. *Simples execução das juntas, leveza dos materiais. *Estanqueidade em junta elástica. *Bolsa com dupla ação: junta elástica e soldável.
B44: 138 | C44: TUBO PVC ESG SR 6M DN100X6M | D44: TUBOS PVC ESGOTO | E44: Instalações prediais industriais, comerciais e residenciais, principalmente quando se exige maiores esforços. | F44: A linha de Esgoto Série Reforçada é utilizada em instalações prediais de esgoto sanitário, água pluvial e ventilação na qual se necessita de uma maior classe de rigidez. Geralmente utilizada em obras verticais com mais de três pavimentos, como: tubos de queda e subcoletores. | G44: *Matéria Prima PVC (Policloreto de Vinila) *Cor: Cinza Claro *Processo: Extrusão *Temperatura Nominal: 75 ͦC (regime não contínuo) *Escoamento por gravidade, não submetida a pressão e ventilação. *Resistência a classe de rigidez de 3.200Pa para os tubos esgoto DN 100 e 150 mm. | H44: *ABNT NBR 5688 *ABNT NBR 8160 | I44: *Resistente a esforços mecânicos e a temperatura. *Fácil instalação. *Simples execução das juntas, leveza dos materiais. *Estanqueidade em junta elástica. *Bolsa com dupla ação: junta elástica e soldável.
B45: 139 | C45: TUBO PVC ESG SR 6M DN150X6M | D45: TUBOS PVC ESGOTO | E45: Instalações prediais industriais, comerciais e residenciais, principalmente quando se exige maiores esforços. | F45: A linha de Esgoto Série Reforçada é utilizada em instalações prediais de esgoto sanitário, água pluvial e ventilação na qual se necessita de uma maior classe de rigidez. Geralmente utilizada em obras verticais com mais de três pavimentos, como: tubos de queda e subcoletores. | G45: *Matéria Prima PVC (Policloreto de Vinila) *Cor: Cinza Claro *Processo: Extrusão *Temperatura Nominal: 75 ͦC (regime não contínuo) *Escoamento por gravidade, não submetida a pressão e ventilação. *Resistência a classe de rigidez de 3.200Pa para os tubos esgoto DN 100 e 150 mm. | H45: *ABNT NBR 5688 *ABNT NBR 8160 | I45: *Resistente a esforços mecânicos e a temperatura. *Fácil instalação. *Simples execução das juntas, leveza dos materiais. *Estanqueidade em junta elástica. *Bolsa com dupla ação: junta elástica e soldável.
B46: 147 | C46: TUBO PPR PN20 20MMX3M | D46: TUBOS PPR | E46: Os Tubos PN20 e PN25 são produzidos em PPR e sua instalação permite encaminhar água quente ou fria aos pontos de consumo | F46: Utilizado em instalação de água quente residencial, comercial, industrial e pode ser embutida em parede de alvenaria, enterrada, parede oca (drywall) e instalações aparentes. | G46: *Material: Polipropileno Copolímero Random PPR. *Material: Polipropileno Copolímero Random PPR. | H46: *ABNT NBR 15813 ○ Parte 1 ○ Parte 2 ○ Parte 3 *ABNT NBR 7198 * DIN 8077 *DIN 8078 *DIN 16962 | I46: *Consulte a tabela de resistência química do PPR disponível no catálogo técnico da linha. *Fácil instalação. * Baixa condutividade térmica. *Economia de energia.
B47: 148 | C47: TUBO PPR PN20 25MMX3M | D47: TUBOS PPR | E47: Os Tubos PN20 e PN25 são produzidos em PPR e sua instalação permite encaminhar água quente ou fria aos pontos de consumo | F47: Utilizado em instalação de água quente residencial, comercial, industrial e pode ser embutida em parede de alvenaria, enterrada, parede oca (drywall) e instalações aparentes. | G47: *Material: Polipropileno Copolímero Random PPR. *Material: Polipropileno Copolímero Random PPR. | H47: *ABNT NBR 15813 ○ Parte 1 ○ Parte 2 ○ Parte 3 *ABNT NBR 7198 * DIN 8077 *DIN 8078 *DIN 16962 | I47: *Consulte a tabela de resistência química do PPR disponível no catálogo técnico da linha. *Fácil instalação. * Baixa condutividade térmica. *Economia de energia.
B48: 149 | C48: TUBO PPR PN20 32MMX3M | D48: TUBOS PPR | E48: Os Tubos PN20 e PN25 são produzidos em PPR e sua instalação permite encaminhar água quente ou fria aos pontos de consumo | F48: Utilizado em instalação de água quente residencial, comercial, industrial e pode ser embutida em parede de alvenaria, enterrada, parede oca (drywall) e instalações aparentes. | G48: *Material: Polipropileno Copolímero Random PPR. *Material: Polipropileno Copolímero Random PPR. | H48: *ABNT NBR 15813 ○ Parte 1 ○ Parte 2 ○ Parte 3 *ABNT NBR 7198 * DIN 8077 *DIN 8078 *DIN 16962 | I48: *Consulte a tabela de resistência química do PPR disponível no catálogo técnico da linha. *Fácil instalação. * Baixa condutividade térmica. *Economia de energia.
B49: 150 | C49: TUBO PPR PN20 40MMX3M | D49: TUBOS PPR | E49: Os Tubos PN20 e PN25 são produzidos em PPR e sua instalação permite encaminhar água quente ou fria aos pontos de consumo | F49: Utilizado em instalação de água quente residencial, comercial, industrial e pode ser embutida em parede de alvenaria, enterrada, parede oca (drywall) e instalações aparentes. | G49: *Material: Polipropileno Copolímero Random PPR. *Material: Polipropileno Copolímero Random PPR. | H49: *ABNT NBR 15813 ○ Parte 1 ○ Parte 2 ○ Parte 3 *ABNT NBR 7198 * DIN 8077 *DIN 8078 *DIN 16962 | I49: *Consulte a tabela de resistência química do PPR disponível no catálogo técnico da linha. *Fácil instalação. * Baixa condutividade térmica. *Economia de energia.
B50: 151 | C50: TUBO PPR PN20 50MMX3M | D50: TUBOS PPR | E50: Os Tubos PN20 e PN25 são produzidos em PPR e sua instalação permite encaminhar água quente ou fria aos pontos de consumo | F50: Utilizado em instalação de água quente residencial, comercial, industrial e pode ser embutida em parede de alvenaria, enterrada, parede oca (drywall) e instalações aparentes. | G50: *Material: Polipropileno Copolímero Random PPR. *Material: Polipropileno Copolímero Random PPR. | H50: *ABNT NBR 15813 ○ Parte 1 ○ Parte 2 ○ Parte 3 *ABNT NBR 7198 * DIN 8077 *DIN 8078 *DIN 16962 | I50: *Consulte a tabela de resistência química do PPR disponível no catálogo técnico da linha. *Fácil instalação. * Baixa condutividade térmica. *Economia de energia.
B51: 152 | C51: TUBO PPR PN20 63MMX3M | D51: TUBOS PPR | E51: Os Tubos PN20 e PN25 são produzidos em PPR e sua instalação permite encaminhar água quente ou fria aos pontos de consumo | F51: Utilizado em instalação de água quente residencial, comercial, industrial e pode ser embutida em parede de alvenaria, enterrada, parede oca (drywall) e instalações aparentes. | G51: *Material: Polipropileno Copolímero Random PPR. *Material: Polipropileno Copolímero Random PPR. | H51: *ABNT NBR 15813 ○ Parte 1 ○ Parte 2 ○ Parte 3 *ABNT NBR 7198 * DIN 8077 *DIN 8078 *DIN 16962 | I51: *Consulte a tabela de resistência química do PPR disponível no catálogo técnico da linha. *Fácil instalação. * Baixa condutividade térmica. *Economia de energia.
...

Sheet Resumo
A1: Família | B1: N° SKUS
A2: ACESSÓRIOS | B2: 53
A3: AF | B3: 395
A4: AQ | B4: 239
A5: ELETRICA | B5: 121
A6: ESGOTO | B6: 239
B7: =SUM(B2:B6) -> 1047

Sheet SB1
A1: SB1
B2: 1 | C2: 2 | D2: 3 | E2: 4 | F2: 5 | G2: 6 | H2: 7 | I2: 8 | J2: 9 | K2: 10 | L2: 11 | M2: 12 | N2: 13 | O2: 14 | P2: 15 | Q2: 16 | R2: 17 | S2: 18 | T2: 19 | U2: 20 | V2: 21 | W2: 22 | X2: 23 | Y2: 24 | Z2: 25 | AA2: 26 | AB2: 27 | AC2: 28 | AD2: 29 | AE2: 30 | AF2: 31 | AG2: 32 | AH2: 33 | AI2: 34 | AJ2: 35 | AK2: 36 | AL2: 37 | AM2: 38 | AN2: 39 | AO2: 40 | AP2: 41 | AQ2: 42 | AR2: 43 | AS2: 44 | AT2: 45 | AU2: 46 | AV2: 47 | AW2: 48 | AX2: 49 | AY2: 50 | AZ2: 51 | BA2: 52 | BB2: 53 | BC2: 54 | BD2: 55 | BE2: 56 | BF2: 57 | BG2: 58 | BH2: 59 | BI2: 60 | BJ2: 61 | BK2: 62 | BL2: 63 | BM2: 64 | BN2: 65 | BO2: 66 | BP2: 67 | BQ2: 68 | BR2: 69 | BS2: 70 | BT2: 71 | BU2: 72 | BV2: 73 | BW2: 74 | BX2: 75 | BY2: 76 | BZ2: 77 | CA2: 78 | CB2: 79 | CC2: 80 | CD2: 81 | CE2: 82 | CF2: 83 | CG2: 84 | CH2: 85 | CI2: 86 | CJ2: 87 | CK2: 88 | CL2: 89 | CM2: 90 | CN2: 91 | CO2: 92 | CP2: 93 | CQ2: 94 | CR2: 95 | CS2: 96 | CT2: 97 | CU2: 98 | CV2: 99 | CW2: 100 | CX2: 101 | CY2: 102 | CZ2: 103 | DA2: 104 | DB2: 105 | DC2: 106 | DD2: 107 | DE2: 108 | DF2: 109 | DG2: 110 | DH2: 111 | DI2: 112 | DJ2: 113 | DK2: 114 | DL2: 115 | DM2: 116 | DN2: 117 | DO2: 118 | DP2: 119 | DQ2: 120 | DR2: 121 | DS2: 122 | DT2: 123 | DU2: 124 | DV2: 125 | DW2: 126 | DX2: 127 | DY2: 128 | DZ2: 129 | EA2: 130 | EB2: 131 | EC2: 132 | ED2: 133 | EE2: 134 | EF2: 135 | EG2: 136 | EH2: 137 | EI2: 138 | EJ2: 139 | EK2: 140 | EL2: 141 | EM2: 142 | EN2: 143 | EO2: 144 | EP2: 145 | EQ2: 146 | ER2: 147 | ES2: 148 | ET2: 149 | EU2: 150 | EV2: 151 | EW2: 152 | EX2: 153 | EY2: 154 | EZ2: 155 | FA2: 156 | FB2: 157 | FC2: 158 | FD2: 159 | FE2: 160 | FF2: 161 | FG2: 162 | FH2: 163 | FI2: 164 | FJ2: 165 | FK2: 166 | FL2: 167 | FM2: 168 | FN2: 169 | FO2: 170 | FP2: 171 | FQ2: 172 | FR2: 173 | FS2: 174 | FT2: 175 | FU2: 176 | FV2: 177 | FW2: 178 | FX2: 179 | FY2: 180 | FZ2: 181 | GA2: 182 | GB2: 183 | GC2: 184 | GD2: 185 | GE2: 186 | GF2: 187 | GG2: 188 | GH2: 189 | GI2: 190 | GJ2: 191 | GK2: 192 | GL2: 193 | GM2: 194 | GN2: 195 | GO2: 196 | GP2: 197 | GQ2: 198 | GR2: 199 | GS2: 200 | GT2: 201 | GU2: 202 | GV2: 203 | GW2: 204 | GX2: 205 | GY2: 206 | GZ2: 207 | HA2: 208 | HB2: 209 | HC2: 210 | HD2: 211 | HE2: 212 | HF2: 213 | HG2: 214 | HH2: 215 | HI2: 216 | HJ2: 217 | HK2: 218 | HL2: 219 | HM2: 220 | HN2: 221 | HO2: 222 | HP2: 223 | HQ2: 224 | HR2: 225 | HS2: 226 | HT2: 227 | HU2: 228 | HV2: 229 | HW2: 230 | HX2: 231 | HY2: 232 | HZ2: 233 | IA2: 234 | IB2: 235 | IC2: 236 | ID2: 237 | IE2: 238 | IF2: 239 | IG2: 240 | IH2: 241 | II2: 242 | IJ2: 243 | IK2: 244 | IL2: 245 | IM2: 246 | IN2: 247 | IO2: 248 | IP2: 249 | IQ2: 250 | IR2: 251 | IS2: 252 | IT2: 253 | IU2: 254 | IV2: 255 | IW2: 256 | IX2: 257 | IY2: 258 | IZ2: 259 | JA2: 260 | JB2: 261 | JC2: 262 | JD2: 263 | JE2: 264 | JF2: 265 | JG2: 266 | JH2: 267 | JI2: 268 | JJ2: 269 | JK2: 270 | JL2: 271 | JM2: 272 | JN2: 273 | JO2: 274 | JP2: 275 | JQ2: 276 | JR2: 277 | JS2: 278 | JT2: 279 | JU2: 280 | JV2: 281 | JW2: 282 | JX2: 283 | JY2: 284 | JZ2: 285 | KA2: 286 | KB2: 287 | KC2: 288 | KD2: 289 | KE2: 290 | KF2: 291 | KG2: 292 | KH2: 293 | KI2: 294 | KJ2: 295 | KK2: 296 | KL2: 297 | KM2: 298 | KN2: 299 | KO2: 300 | KP2: 301 | KQ2: 302 | KR2: 303 | KS2: 304 | KT2: 305 | KU2: 306 | KV2: 307 | KW2: 308 | KX2: 309 | KY2: 310 | KZ2: 311 | LA2: 312 | LB2: 313 | LC2: 314 | LD2: 315 | LE2: 316 | LF2: 317 | LG2: 318 | LH2: 319 | LI2: 320
A3: Filial | B3: Codigo | C3: Descricao | D3: Tipo | E3: Unidade | F3: Local Padrao | G3: Grupo | H3: Aliq. ICMS | I3: Pos.IPI/NCM | J3: Ex-NCM | K3: Ex-NBM | L3: Especie TIPI | M3: Aliq. IPI | N3: Aliq. ISS | O3: Cod.Serv.ISS | P3: TE Padrao | Q3: TS Padrao | R3: Solid. Saida | S3: Solid. Entr. | T3: Foto | U3: Seg.Un.Medi. | V3: Imp.Z.Franca | W3: Tipo de Conv | X3: Fator Conv. | Y3: Alternativo | Z3: Qtd.Embalag. | AA3: Preco Venda | AB3: Ponto Pedido | AC3: Custo Stand. | AD3: Ult. Compra | AE3: Ult. Preco | AF3: Peso Liquido | AG3: Form.Est.Seg | AH3: Seguranca | AI3: Form. Prazo | AJ3: Entrega | AK3: Tipo Prazo | AL3: Lote Econom. | AM3: Lote Minimo | AN3: Cta Contabil | AO3: Tolerancia | AP3: C Custo | AQ3: Familia | AR3: Loja Padrao | AS3: Forn. Padrao | AT3: Base Estrut. | AU3: Apropriacao | AV3: Fantasma | AW3: Tipo Dec. OP | AX3: Origem | AY3: DT Referenc. | AZ3: Class.Fiscal | BA3: Ult. Revisao | BB3: Rastro | BC3: Fora estado | BD3: % Comissao | BE3: Forn. Canal | BF3: Entra MRP | BG3: Dt.Ref.Prc 1 | BH3: Per.Invent. | BI3: Grupo Trib. | BJ3: Nota Minima | BK3: Prazo Valid. | BL3: Cont.Seg.Soc | BM3: Cons.Inicial | BN3: Qtde. Copias | BO3: Cod Barras | BP3: Grade | BQ3: Cod Form Lot | BR3: Impos.Renda | BS3: Contr.Locali | BT3: Contrato | BU3: Desc. Portug | BV3: Rt.Op Padrao | BW3: Cod.Familia | BX3: Desc. Ingles | BY3: Linha | BZ3: Desc. L.I. | CA3: Val.Ref.US$ | CB3: Anuente ? | CC3: Opc. Default | CD3: Cod. Obs. | CE3: Prod. Import | CF3: Situacao | CG3: Fabricante | CH3: Gera OP Auto | CI3: Modelo | CJ3: Setor | CK3: Balanca | CL3: Produto Pai | CM3: Tecla | CN3: Tipo de C.Q. | CO3: Restricao | CP3: Gr. Compras | CQ3: Desv Padrao | CR3: Calc. FETHAB | CS3: Pauta FETHAB | CT3: PIS Pauta | CU3: COFINS Pauta | CV3: Ret.Operacao | CW3: Produ‡”es CQ | CX3: Pr.Fundersul | CY3: Cont.Prod.CQ | CZ3: P.M.kg/Prev. | DA3: Rev.Estrutur | DB3: Dem.Prevista | DC3: Calcula INSS | DD3: Classe Repos | DE3: Espec.Mater. | DF3: Custeio OP | DG3: Materia Pri. | DH3: % Red.PIS | DI3: ALADI | DJ3: Frac Permit | DK3: Status Venda | DL3: % Red.COFINS | DM3: Cod Item | DN3: MTTR em Hr. | DO3: Data Substit | DP3: P.ICMS Prop. | DQ3: Perc. COFINS | DR3: Gr Cnt Custo | DS3: Perc. CSLL | DT3: CC p/ Custo | DU3: Perc. PIS | DV3: Cód. ant. | DW3: Qtde. Midia | DX3: Inc.FETHAB | DY3: % Red. INSS | DZ3: Crd Estímulo | EA3: % Red. IRRF | EB3: C.Bar.Embal. | EC3: IPI de Pauta | ED3: Base ST R.SC | EE3: Aliq FECP | EF3: Est.Limite | EG3: Nova Emb | EH3: Cal. IVA Aju | EI3: Fust/Funttel | EJ3: Regra ISS Pg | EK3: Tp Pad.Reemb | EL3: C.B.Unitiz | EM3: C. Trib. Mun | EN3: Emb.Padrao | EO3: Imp.Direta | EP3: Embalagem | EQ3: Env. Obrigat | ER3: Parceiro | ES3: Tip Sugestao | ET3: % Macronutr. | EU3: Grupo Descon | EV3: % Micronutr. | EW3: Item Conta | EX3: Dep Correcao | EY3: Moeda C.Std | EZ3: Base Pre-Es. | FA3: Calc.Midia | FB3: IPI de Pauta | FC3: MTBF em Hr. | FD3: Reembalagem | FE3: NALADI NCCA | FF3: Qt. Reemb. | FG3: NALADI SH | FH3: Cd.Bar.Reemb | FI3: Serie/Colec. | FJ3: Nr.faixas CD | FK3: Nro. Paginas | FL3: Codigo ISBN | FM3: Rel. Prodepe | FN3: Tit.Original | FO3: Tipo Medic. | FP3: Alq. FUMACOP | FQ3: Prod. RN 944 | FR3: % Markup | FS3: Insp.Normal? | FT3: Grp.Nat.Rec. | FU3: Lingua Orig. | FV3: Nro.Edicao | FW3: Obs ISBN | FX3: Dt.Fim N. R. | FY3: Cod Cl Val | FZ3: Ativo | GA3: Peso Bruto | GB3: Fora PP ate? | GC3: Tipo Carga | GD3: Alm.Entr | GE3: Icms Pauta | GF3: Des SubFam | GG3: Valor Selo | GH3: SFamilia | GI3: Trunc ou Arr | GJ3: Prop ou Terc | GK3: Tamanho | GL3: Cód.Desc.Pro | GM3: Grau Dificul | GN3: Valor CIF | GO3: Atende Nec? | GP3: Vale Present | GQ3: Lote SBP | GR3: Tipo BN | GS3: Des SubFam | GT3: Admin. | GU3: Qt.Lim.Etiq. | GV3: Loc. Fisica | GW3: Perda Confor | GX3: SubSubFamil | GY3: Garantia? | GZ3: Tipo Vetor | HA3: Cod Familia | HB3: % Garantia | HC3: Estr. Origem | HD3: Cod. Norma | HE3: % Promocao | HF3: Descto Ger. | HG3: Cubagem | HH3: Cor | HI3: Integracao | HJ3: Cod. GTIN | HK3: Integ.Portal | HL3: Exp. Alcis | HM3: Vld Num Seri | HN3: Est.Min.Inve | HO3: Grp Mix Alvo | HP3: Peso MCP | HQ3: Desconto Rep | HR3: Ult. Calculo | HS3: Contr. Poten | HT3: Potencia Pad | HU3: Qtde. Acum. | HV3: Class. Produ | HW3: Qtd Inic Mes | HX3: Estoq Maximo | HY3: Ult Moe Comp | HZ3: Calcula PIS | IA3: Ult Vlr Comp | IB3: Calc. COFINS | IC3: Nivel Tabela | ID3: Calcula CSLL | IE3: C. Atividade | IF3: Qt. Unitizad | IG3: Dt.Lancament | IH3: Tipo Etiquet | II3: Dt.Descontin | IJ3: Cor Princip. | IK3: Cor Secund. | IL3: Icone APS | IM3: Atributo 1 | IN3: Atributo 2 | IO3: Atributo 3 | IP3: Regra Sequ. | IQ3: Requisitado | IR3: Bloqueado | IS3: Utiliza Selo | IT3: Qtde Venda | IU3: OK | IV3: Classe Selo | IW3: Tp. Reg | IX3: F.Ret.ISS | IY3: FEFO | IZ3: Est Cred IPI | JA3: Cred. ICMS | JB3: Código EAN | JC3: Desp.Import. | JD3: Enq. Selo | JE3: Aliq. FECOP | JF3: Al. FECOP ST | JG3: Calc. FECOP | JH3: Material Rec | JI3: Data Vigenc | JJ3: %Crd. Pres. | JK3: Aliq. FETHAB | JL3: Aliq. FACS | JM3: Aliq. FABOV | JN3: Tipo FETHAB | JO3: Ref. Base | JP3: Cod.Orig. | JQ3: Art65 RICMPR | JR3: Cal. CFEM | JS3: Sit. CFEM | JT3: Aliq. CFEMA | JU3: Mud.Reg.Trib | JV3: Cod.Cat83 | JW3: %Red.43080 | JX3: Tab. Nat. Re | JY3: Cod Nat Rece | JZ3: Chassi | KA3: Aliq FECP BA | KB3: Dif. CNAE | KC3: Prod. DCI | KD3: Nr. DCRE | KE3: Nr. DCR | KF3: Vl. DCRII | KG3: Coef. DCR | KH3: Pr.Inc.Leite | KI3: Ali.FECOP-RN | KJ3: Rg. Simp. MT | KK3: Cont ICMS-ST | KL3: Rastro Ativo | KM3: Ajust/Difer | KN3: Exe. Servico | KO3: Sit Trib | KP3: Carga Esp? | KQ3: Grupo - TI | KR3: Enq. IPI | KS3: CEST | KT3: Alq.FUNDESA | KU3: Alíq. IMA-MT | KV3: Alíq.FASE-MT | KW3: Porc. PRL | KX3: Aliq. FAMAD | KY3: Calc. TPDP | KZ3: Aliq. de Imp | LA3: Terc Un Med | LB3: Hr. Ult. Exp | LC3: ID.Hist. | LD3: Ident.Export | LE3: MD5 | LF3: Peso Uni Emb | LG3: Ap. p/ Prod. | LH3: Lote Maximo | LI3: Perc. Aponta
